[2025-08-05T02:13:01.040+0000] {taskinstance.py:1956} INFO - Dependencies all met for dep_context=non-requeueable deps ti=<TaskInstance: Ejercicio1.LoadAndSetDimCustomerSegment manual__2025-08-05T02:12:41.060718+00:00 [queued]>
[2025-08-05T02:13:01.072+0000] {taskinstance.py:1956} INFO - Dependencies all met for dep_context=requeueable deps ti=<TaskInstance: Ejercicio1.LoadAndSetDimCustomerSegment manual__2025-08-05T02:12:41.060718+00:00 [queued]>
[2025-08-05T02:13:01.074+0000] {taskinstance.py:2170} INFO - Starting attempt 1 of 2
[2025-08-05T02:13:01.145+0000] {taskinstance.py:2191} INFO - Executing <Task(PythonOperator): LoadAndSetDimCustomerSegment> on 2025-08-05 02:12:41.060718+00:00
[2025-08-05T02:13:01.175+0000] {standard_task_runner.py:60} INFO - Started process 1426 to run task
[2025-08-05T02:13:01.194+0000] {standard_task_runner.py:87} INFO - Running: ['***', 'tasks', 'run', 'Ejercicio1', 'LoadAndSetDimCustomerSegment', 'manual__2025-08-05T02:12:41.060718+00:00', '--job-id', '60', '--raw', '--subdir', 'DAGS_FOLDER/ejercicio1.py', '--cfg-path', '/tmp/tmp0mqg2b4i']
[2025-08-05T02:13:01.207+0000] {standard_task_runner.py:88} INFO - Job 60: Subtask LoadAndSetDimCustomerSegment
[2025-08-05T02:13:01.531+0000] {task_command.py:423} INFO - Running <TaskInstance: Ejercicio1.LoadAndSetDimCustomerSegment manual__2025-08-05T02:12:41.060718+00:00 [running]> on host e9748c04215f
[2025-08-05T02:13:02.035+0000] {taskinstance.py:2480} INFO - Exporting env vars: AIRFLOW_CTX_DAG_OWNER='***' AIRFLOW_CTX_DAG_ID='Ejercicio1' AIRFLOW_CTX_TASK_ID='LoadAndSetDimCustomerSegment' AIRFLOW_CTX_EXECUTION_DATE='2025-08-05T02:12:41.060718+00:00' AIRFLOW_CTX_TRY_NUMBER='1' AIRFLOW_CTX_DAG_RUN_ID='manual__2025-08-05T02:12:41.060718+00:00'
[2025-08-05T02:13:02.058+0000] {taskinstance.py:2698} ERROR - Task failed with exception
Traceback (most recent call last):
  File "/home/airflow/.local/lib/python3.8/site-packages/airflow/models/taskinstance.py", line 433, in _execute_task
    result = execute_callable(context=context, **execute_callable_kwargs)
  File "/home/airflow/.local/lib/python3.8/site-packages/airflow/operators/python.py", line 199, in execute
    return_value = self.execute_callable()
  File "/home/airflow/.local/lib/python3.8/site-packages/airflow/operators/python.py", line 216, in execute_callable
    return self.python_callable(*self.op_args, **self.op_kwargs)
  File "/opt/airflow/dags/ejercicio1.py", line 114, in call
    set_lastid(table, cond,engine)
  File "/opt/airflow/dags/ejercicio1.py", line 93, in set_lastid
    supabase = create_client(os.getenv('URL_SUPABASE'), os.getenv('TOKEN_SUPABASE'))
  File "/home/airflow/.local/lib/python3.8/site-packages/supabase/_sync/client.py", line 295, in create_client
    return SyncClient.create(
  File "/home/airflow/.local/lib/python3.8/site-packages/supabase/_sync/client.py", line 97, in create
    client = cls(supabase_url, supabase_key, options)
  File "/home/airflow/.local/lib/python3.8/site-packages/supabase/_sync/client.py", line 75, in __init__
    self.auth = self._init_supabase_auth_client(
  File "/home/airflow/.local/lib/python3.8/site-packages/supabase/_sync/client.py", line 217, in _init_supabase_auth_client
    return SyncSupabaseAuthClient(
  File "/home/airflow/.local/lib/python3.8/site-packages/supabase/_sync/auth_client.py", line 31, in __init__
    SyncGoTrueClient.__init__(
  File "/home/airflow/.local/lib/python3.8/site-packages/gotrue/_sync/gotrue_client.py", line 101, in __init__
    SyncGoTrueBaseAPI.__init__(
  File "/home/airflow/.local/lib/python3.8/site-packages/gotrue/_sync/gotrue_base_api.py", line 28, in __init__
    self._http_client = http_client or SyncClient(
TypeError: __init__() got an unexpected keyword argument 'proxy'
[2025-08-05T02:13:02.144+0000] {taskinstance.py:1138} INFO - Marking task as UP_FOR_RETRY. dag_id=Ejercicio1, task_id=LoadAndSetDimCustomerSegment, execution_date=20250805T021241, start_date=20250805T021301, end_date=20250805T021302
[2025-08-05T02:13:02.195+0000] {standard_task_runner.py:107} ERROR - Failed to execute job 60 for task LoadAndSetDimCustomerSegment (__init__() got an unexpected keyword argument 'proxy'; 1426)
[2025-08-05T02:13:02.268+0000] {local_task_job_runner.py:234} INFO - Task exited with return code 1
[2025-08-05T02:13:02.396+0000] {taskinstance.py:3280} INFO - 0 downstream tasks scheduled from follow-on schedule check
