[2025-08-05T23:30:26.402+0000] {taskinstance.py:1956} INFO - Dependencies all met for dep_context=non-requeueable deps ti=<TaskInstance: Ejercicio1.Updatedimcustomersegment manual__2025-08-05T23:30:10.642566+00:00 [queued]>
[2025-08-05T23:30:26.454+0000] {taskinstance.py:1956} INFO - Dependencies all met for dep_context=requeueable deps ti=<TaskInstance: Ejercicio1.Updatedimcustomersegment manual__2025-08-05T23:30:10.642566+00:00 [queued]>
[2025-08-05T23:30:26.457+0000] {taskinstance.py:2170} INFO - Starting attempt 1 of 2
[2025-08-05T23:30:26.537+0000] {taskinstance.py:2191} INFO - Executing <Task(PythonOperator): Updatedimcustomersegment> on 2025-08-05 23:30:10.642566+00:00
[2025-08-05T23:30:26.569+0000] {standard_task_runner.py:60} INFO - Started process 3402 to run task
[2025-08-05T23:30:26.587+0000] {standard_task_runner.py:87} INFO - Running: ['***', 'tasks', 'run', 'Ejercicio1', 'Updatedimcustomersegment', 'manual__2025-08-05T23:30:10.642566+00:00', '--job-id', '237', '--raw', '--subdir', 'DAGS_FOLDER/ejercicio1.py', '--cfg-path', '/tmp/tmp503qp7jx']
[2025-08-05T23:30:26.607+0000] {standard_task_runner.py:88} INFO - Job 237: Subtask Updatedimcustomersegment
[2025-08-05T23:30:26.904+0000] {task_command.py:423} INFO - Running <TaskInstance: Ejercicio1.Updatedimcustomersegment manual__2025-08-05T23:30:10.642566+00:00 [running]> on host 019b67754667
[2025-08-05T23:30:27.277+0000] {taskinstance.py:2480} INFO - Exporting env vars: AIRFLOW_CTX_DAG_OWNER='***' AIRFLOW_CTX_DAG_ID='Ejercicio1' AIRFLOW_CTX_TASK_ID='Updatedimcustomersegment' AIRFLOW_CTX_EXECUTION_DATE='2025-08-05T23:30:10.642566+00:00' AIRFLOW_CTX_TRY_NUMBER='1' AIRFLOW_CTX_DAG_RUN_ID='manual__2025-08-05T23:30:10.642566+00:00'
[2025-08-05T23:30:28.121+0000] {_client.py:1038} INFO - HTTP Request: GET https://qwpzsjaaxuijmqodvslf.supabase.co/rest/v1/stg_dimcustomersegment?select=%2A "HTTP/2 200 OK"
[2025-08-05T23:30:28.169+0000] {taskinstance.py:2698} ERROR - Task failed with exception
Traceback (most recent call last):
  File "/home/airflow/.local/lib/python3.8/site-packages/airflow/models/taskinstance.py", line 433, in _execute_task
    result = execute_callable(context=context, **execute_callable_kwargs)
  File "/home/airflow/.local/lib/python3.8/site-packages/airflow/operators/python.py", line 199, in execute
    return_value = self.execute_callable()
  File "/home/airflow/.local/lib/python3.8/site-packages/airflow/operators/python.py", line 216, in execute_callable
    return self.python_callable(*self.op_args, **self.op_kwargs)
  File "/opt/airflow/dags/ejercicio1.py", line 147, in call
    update_inactive(table,id,engine)
  File "/opt/airflow/dags/ejercicio1.py", line 47, in update_inactive
    if not df_supabase.empty():
TypeError: 'bool' object is not callable
[2025-08-05T23:30:28.219+0000] {taskinstance.py:1138} INFO - Marking task as UP_FOR_RETRY. dag_id=Ejercicio1, task_id=Updatedimcustomersegment, execution_date=20250805T233010, start_date=20250805T233026, end_date=20250805T233028
[2025-08-05T23:30:28.263+0000] {standard_task_runner.py:107} ERROR - Failed to execute job 237 for task Updatedimcustomersegment ('bool' object is not callable; 3402)
[2025-08-05T23:30:28.327+0000] {local_task_job_runner.py:234} INFO - Task exited with return code 1
[2025-08-05T23:30:28.420+0000] {taskinstance.py:3280} INFO - 0 downstream tasks scheduled from follow-on schedule check
