[2025-08-05T19:22:57.731+0000] {taskinstance.py:1956} INFO - Dependencies all met for dep_context=non-requeueable deps ti=<TaskInstance: Ejercicio1.LoadAndSetdimdate manual__2025-08-05T19:17:26.004830+00:00 [queued]>
[2025-08-05T19:22:57.754+0000] {taskinstance.py:1956} INFO - Dependencies all met for dep_context=requeueable deps ti=<TaskInstance: Ejercicio1.LoadAndSetdimdate manual__2025-08-05T19:17:26.004830+00:00 [queued]>
[2025-08-05T19:22:57.755+0000] {taskinstance.py:2170} INFO - Starting attempt 2 of 2
[2025-08-05T19:22:57.800+0000] {taskinstance.py:2191} INFO - Executing <Task(PythonOperator): LoadAndSetdimdate> on 2025-08-05 19:17:26.004830+00:00
[2025-08-05T19:22:57.821+0000] {standard_task_runner.py:60} INFO - Started process 1018 to run task
[2025-08-05T19:22:57.826+0000] {standard_task_runner.py:87} INFO - Running: ['***', 'tasks', 'run', 'Ejercicio1', 'LoadAndSetdimdate', 'manual__2025-08-05T19:17:26.004830+00:00', '--job-id', '134', '--raw', '--subdir', 'DAGS_FOLDER/ejercicio1.py', '--cfg-path', '/tmp/tmpz2soscll']
[2025-08-05T19:22:57.832+0000] {standard_task_runner.py:88} INFO - Job 134: Subtask LoadAndSetdimdate
[2025-08-05T19:22:57.967+0000] {task_command.py:423} INFO - Running <TaskInstance: Ejercicio1.LoadAndSetdimdate manual__2025-08-05T19:17:26.004830+00:00 [running]> on host 019b67754667
[2025-08-05T19:22:58.218+0000] {taskinstance.py:2480} INFO - Exporting env vars: AIRFLOW_CTX_DAG_OWNER='***' AIRFLOW_CTX_DAG_ID='Ejercicio1' AIRFLOW_CTX_TASK_ID='LoadAndSetdimdate' AIRFLOW_CTX_EXECUTION_DATE='2025-08-05T19:17:26.004830+00:00' AIRFLOW_CTX_TRY_NUMBER='2' AIRFLOW_CTX_DAG_RUN_ID='manual__2025-08-05T19:17:26.004830+00:00'
[2025-08-05T19:22:58.345+0000] {logging_mixin.py:188} INFO -      dateid        date  Year  Quarter  ... Monthname  Day Weekday  WeekdayName
0         1  2019-03-09  2019        1  ...     March    9       7       Sunday
1         2  2019-03-10  2019        1  ...     March   10       1       Monday
2         3  2019-03-11  2019        1  ...     March   11       2      Tuesday
3         4  2019-03-12  2019        1  ...     March   12       3    Wednesday
4         5  2019-03-13  2019        1  ...     March   13       4     Thursday
..      ...         ...   ...      ...  ...       ...  ...     ...          ...
345     346  2020-02-17  2020        1  ...  February   17       2      Tuesday
346     347  2020-02-18  2020        1  ...  February   18       3    Wednesday
347     348  2020-02-19  2020        1  ...  February   19       4     Thursday
348     349  2020-02-20  2020        1  ...  February   20       5       Friday
349     350  2020-02-21  2020        1  ...  February   21       6     Saturday

[350 rows x 10 columns]
[2025-08-05T19:22:58.347+0000] {taskinstance.py:2698} ERROR - Task failed with exception
Traceback (most recent call last):
  File "/home/airflow/.local/lib/python3.8/site-packages/pandas/core/indexes/base.py", line 3653, in get_loc
    return self._engine.get_loc(casted_key)
  File "pandas/_libs/index.pyx", line 147, in pandas._libs.index.IndexEngine.get_loc
  File "pandas/_libs/index.pyx", line 176, in pandas._libs.index.IndexEngine.get_loc
  File "pandas/_libs/hashtable_class_helper.pxi", line 7080, in pandas._libs.hashtable.PyObjectHashTable.get_item
  File "pandas/_libs/hashtable_class_helper.pxi", line 7088, in pandas._libs.hashtable.PyObjectHashTable.get_item
KeyError: 'Productid'

The above exception was the direct cause of the following exception:

Traceback (most recent call last):
  File "/home/airflow/.local/lib/python3.8/site-packages/airflow/models/taskinstance.py", line 433, in _execute_task
    result = execute_callable(context=context, **execute_callable_kwargs)
  File "/home/airflow/.local/lib/python3.8/site-packages/airflow/operators/python.py", line 199, in execute
    return_value = self.execute_callable()
  File "/home/airflow/.local/lib/python3.8/site-packages/airflow/operators/python.py", line 216, in execute_callable
    return self.python_callable(*self.op_args, **self.op_kwargs)
  File "/opt/airflow/dags/ejercicio1.py", line 112, in call
    set_lastid(table,id,engine)
  File "/opt/airflow/dags/ejercicio1.py", line 97, in set_lastid
    last_id = df[cond].max()
  File "/home/airflow/.local/lib/python3.8/site-packages/pandas/core/frame.py", line 3761, in __getitem__
    indexer = self.columns.get_loc(key)
  File "/home/airflow/.local/lib/python3.8/site-packages/pandas/core/indexes/base.py", line 3655, in get_loc
    raise KeyError(key) from err
KeyError: 'Productid'
[2025-08-05T19:22:58.394+0000] {taskinstance.py:1138} INFO - Marking task as FAILED. dag_id=Ejercicio1, task_id=LoadAndSetdimdate, execution_date=20250805T191726, start_date=20250805T192257, end_date=20250805T192258
[2025-08-05T19:22:58.433+0000] {standard_task_runner.py:107} ERROR - Failed to execute job 134 for task LoadAndSetdimdate ('Productid'; 1018)
[2025-08-05T19:22:58.499+0000] {local_task_job_runner.py:234} INFO - Task exited with return code 1
[2025-08-05T19:22:58.595+0000] {taskinstance.py:3280} INFO - 0 downstream tasks scheduled from follow-on schedule check
