[2025-08-05T18:58:23.222+0000] {taskinstance.py:1956} INFO - Dependencies all met for dep_context=non-requeueable deps ti=<TaskInstance: Ejercicio1.LoadAndSetdimdate manual__2025-08-05T18:58:06.618199+00:00 [queued]>
[2025-08-05T18:58:23.263+0000] {taskinstance.py:1956} INFO - Dependencies all met for dep_context=requeueable deps ti=<TaskInstance: Ejercicio1.LoadAndSetdimdate manual__2025-08-05T18:58:06.618199+00:00 [queued]>
[2025-08-05T18:58:23.265+0000] {taskinstance.py:2170} INFO - Starting attempt 1 of 2
[2025-08-05T18:58:23.502+0000] {taskinstance.py:2191} INFO - Executing <Task(PythonOperator): LoadAndSetdimdate> on 2025-08-05 18:58:06.618199+00:00
[2025-08-05T18:58:23.524+0000] {standard_task_runner.py:60} INFO - Started process 587 to run task
[2025-08-05T18:58:23.568+0000] {standard_task_runner.py:87} INFO - Running: ['***', 'tasks', 'run', 'Ejercicio1', 'LoadAndSetdimdate', 'manual__2025-08-05T18:58:06.618199+00:00', '--job-id', '98', '--raw', '--subdir', 'DAGS_FOLDER/ejercicio1.py', '--cfg-path', '/tmp/tmplawfdy7q']
[2025-08-05T18:58:23.590+0000] {standard_task_runner.py:88} INFO - Job 98: Subtask LoadAndSetdimdate
[2025-08-05T18:58:24.752+0000] {task_command.py:423} INFO - Running <TaskInstance: Ejercicio1.LoadAndSetdimdate manual__2025-08-05T18:58:06.618199+00:00 [running]> on host 019b67754667
[2025-08-05T18:58:26.372+0000] {taskinstance.py:2480} INFO - Exporting env vars: AIRFLOW_CTX_DAG_OWNER='***' AIRFLOW_CTX_DAG_ID='Ejercicio1' AIRFLOW_CTX_TASK_ID='LoadAndSetdimdate' AIRFLOW_CTX_EXECUTION_DATE='2025-08-05T18:58:06.618199+00:00' AIRFLOW_CTX_TRY_NUMBER='1' AIRFLOW_CTX_DAG_RUN_ID='manual__2025-08-05T18:58:06.618199+00:00'
[2025-08-05T18:58:26.617+0000] {logging_mixin.py:188} INFO - 
 ---------------SE ENCONTRAROS DATOS PARA LA CARGA INICIAL | ULTIMO ID DE LA TABLA:350-----------------
[2025-08-05T18:58:27.189+0000] {taskinstance.py:2698} ERROR - Task failed with exception
Traceback (most recent call last):
  File "/home/airflow/.local/lib/python3.8/site-packages/airflow/models/taskinstance.py", line 433, in _execute_task
    result = execute_callable(context=context, **execute_callable_kwargs)
  File "/home/airflow/.local/lib/python3.8/site-packages/airflow/operators/python.py", line 199, in execute
    return_value = self.execute_callable()
  File "/home/airflow/.local/lib/python3.8/site-packages/airflow/operators/python.py", line 216, in execute_callable
    return self.python_callable(*self.op_args, **self.op_kwargs)
  File "/opt/airflow/dags/ejercicio1.py", line 110, in call
    set_lastid(table, cond,engine)
  File "/opt/airflow/dags/ejercicio1.py", line 98, in set_lastid
    load_supabase(table, df)
  File "/opt/airflow/dags/ejercicio1.py", line 20, in load_supabase
    df = df.drop(columns=['index'])
  File "/home/airflow/.local/lib/python3.8/site-packages/pandas/core/frame.py", line 5258, in drop
    return super().drop(
  File "/home/airflow/.local/lib/python3.8/site-packages/pandas/core/generic.py", line 4549, in drop
    obj = obj._drop_axis(labels, axis, level=level, errors=errors)
  File "/home/airflow/.local/lib/python3.8/site-packages/pandas/core/generic.py", line 4591, in _drop_axis
    new_axis = axis.drop(labels, errors=errors)
  File "/home/airflow/.local/lib/python3.8/site-packages/pandas/core/indexes/base.py", line 6699, in drop
    raise KeyError(f"{list(labels[mask])} not found in axis")
KeyError: "['index'] not found in axis"
[2025-08-05T18:58:27.310+0000] {taskinstance.py:1138} INFO - Marking task as UP_FOR_RETRY. dag_id=Ejercicio1, task_id=LoadAndSetdimdate, execution_date=20250805T185806, start_date=20250805T185823, end_date=20250805T185827
[2025-08-05T18:58:27.586+0000] {standard_task_runner.py:107} ERROR - Failed to execute job 98 for task LoadAndSetdimdate ("['index'] not found in axis"; 587)
[2025-08-05T18:58:27.694+0000] {local_task_job_runner.py:234} INFO - Task exited with return code 1
[2025-08-05T18:58:27.823+0000] {taskinstance.py:3280} INFO - 0 downstream tasks scheduled from follow-on schedule check
