[2025-08-05T01:43:37.586+0000] {taskinstance.py:1956} INFO - Dependencies all met for dep_context=non-requeueable deps ti=<TaskInstance: Ejercicio1.LoadAndSetDimCustomerSegment manual__2025-08-05T01:43:13.140391+00:00 [queued]>
[2025-08-05T01:43:37.639+0000] {taskinstance.py:1956} INFO - Dependencies all met for dep_context=requeueable deps ti=<TaskInstance: Ejercicio1.LoadAndSetDimCustomerSegment manual__2025-08-05T01:43:13.140391+00:00 [queued]>
[2025-08-05T01:43:37.640+0000] {taskinstance.py:2170} INFO - Starting attempt 1 of 2
[2025-08-05T01:43:37.773+0000] {taskinstance.py:2191} INFO - Executing <Task(PythonOperator): LoadAndSetDimCustomerSegment> on 2025-08-05 01:43:13.140391+00:00
[2025-08-05T01:43:37.838+0000] {standard_task_runner.py:60} INFO - Started process 970 to run task
[2025-08-05T01:43:37.899+0000] {standard_task_runner.py:87} INFO - Running: ['***', 'tasks', 'run', 'Ejercicio1', 'LoadAndSetDimCustomerSegment', 'manual__2025-08-05T01:43:13.140391+00:00', '--job-id', '43', '--raw', '--subdir', 'DAGS_FOLDER/ejercicio1.py', '--cfg-path', '/tmp/tmpfvztkk7j']
[2025-08-05T01:43:37.930+0000] {standard_task_runner.py:88} INFO - Job 43: Subtask LoadAndSetDimCustomerSegment
[2025-08-05T01:43:38.496+0000] {task_command.py:423} INFO - Running <TaskInstance: Ejercicio1.LoadAndSetDimCustomerSegment manual__2025-08-05T01:43:13.140391+00:00 [running]> on host e9748c04215f
[2025-08-05T01:43:39.068+0000] {taskinstance.py:2480} INFO - Exporting env vars: AIRFLOW_CTX_DAG_OWNER='***' AIRFLOW_CTX_DAG_ID='Ejercicio1' AIRFLOW_CTX_TASK_ID='LoadAndSetDimCustomerSegment' AIRFLOW_CTX_EXECUTION_DATE='2025-08-05T01:43:13.140391+00:00' AIRFLOW_CTX_TRY_NUMBER='1' AIRFLOW_CTX_DAG_RUN_ID='manual__2025-08-05T01:43:13.140391+00:00'
[2025-08-05T01:43:39.133+0000] {taskinstance.py:2698} ERROR - Task failed with exception
Traceback (most recent call last):
  File "/home/airflow/.local/lib/python3.8/site-packages/sqlalchemy/engine/base.py", line 1910, in _execute_context
    self.dialect.do_execute(
  File "/home/airflow/.local/lib/python3.8/site-packages/sqlalchemy/engine/default.py", line 736, in do_execute
    cursor.execute(statement, parameters)
psycopg2.errors.UndefinedTable: relation "DimCustomerSegment" does not exist
LINE 1: SELECT * FROM "DimCustomerSegment"
                      ^


The above exception was the direct cause of the following exception:

Traceback (most recent call last):
  File "/home/airflow/.local/lib/python3.8/site-packages/airflow/models/taskinstance.py", line 433, in _execute_task
    result = execute_callable(context=context, **execute_callable_kwargs)
  File "/home/airflow/.local/lib/python3.8/site-packages/airflow/operators/python.py", line 199, in execute
    return_value = self.execute_callable()
  File "/home/airflow/.local/lib/python3.8/site-packages/airflow/operators/python.py", line 216, in execute_callable
    return self.python_callable(*self.op_args, **self.op_kwargs)
  File "/opt/airflow/dags/ejercicio1.py", line 61, in call
    set_lastid(table, cond,engine)
  File "/opt/airflow/dags/ejercicio1.py", line 45, in set_lastid
    df = pd.read_sql(f'SELECT * FROM "{table}"', engine)
  File "/home/airflow/.local/lib/python3.8/site-packages/pandas/io/sql.py", line 663, in read_sql
    return pandas_sql.read_query(
  File "/home/airflow/.local/lib/python3.8/site-packages/pandas/io/sql.py", line 1738, in read_query
    result = self.execute(sql, params)
  File "/home/airflow/.local/lib/python3.8/site-packages/pandas/io/sql.py", line 1562, in execute
    return self.con.exec_driver_sql(sql, *args)
  File "/home/airflow/.local/lib/python3.8/site-packages/sqlalchemy/engine/base.py", line 1770, in exec_driver_sql
    return self._exec_driver_sql(
  File "/home/airflow/.local/lib/python3.8/site-packages/sqlalchemy/engine/base.py", line 1674, in _exec_driver_sql
    ret = self._execute_context(
  File "/home/airflow/.local/lib/python3.8/site-packages/sqlalchemy/engine/base.py", line 1953, in _execute_context
    self._handle_dbapi_exception(
  File "/home/airflow/.local/lib/python3.8/site-packages/sqlalchemy/engine/base.py", line 2134, in _handle_dbapi_exception
    util.raise_(
  File "/home/airflow/.local/lib/python3.8/site-packages/sqlalchemy/util/compat.py", line 211, in raise_
    raise exception
  File "/home/airflow/.local/lib/python3.8/site-packages/sqlalchemy/engine/base.py", line 1910, in _execute_context
    self.dialect.do_execute(
  File "/home/airflow/.local/lib/python3.8/site-packages/sqlalchemy/engine/default.py", line 736, in do_execute
    cursor.execute(statement, parameters)
sqlalchemy.exc.ProgrammingError: (psycopg2.errors.UndefinedTable) relation "DimCustomerSegment" does not exist
LINE 1: SELECT * FROM "DimCustomerSegment"
                      ^

[SQL: SELECT * FROM "DimCustomerSegment"]
(Background on this error at: https://sqlalche.me/e/14/f405)
[2025-08-05T01:43:39.184+0000] {taskinstance.py:1138} INFO - Marking task as UP_FOR_RETRY. dag_id=Ejercicio1, task_id=LoadAndSetDimCustomerSegment, execution_date=20250805T014313, start_date=20250805T014337, end_date=20250805T014339
[2025-08-05T01:43:39.249+0000] {standard_task_runner.py:107} ERROR - Failed to execute job 43 for task LoadAndSetDimCustomerSegment ((psycopg2.errors.UndefinedTable) relation "DimCustomerSegment" does not exist
LINE 1: SELECT * FROM "DimCustomerSegment"
                      ^

[SQL: SELECT * FROM "DimCustomerSegment"]
(Background on this error at: https://sqlalche.me/e/14/f405); 970)
[2025-08-05T01:43:39.310+0000] {local_task_job_runner.py:234} INFO - Task exited with return code 1
[2025-08-05T01:43:39.394+0000] {taskinstance.py:3280} INFO - 0 downstream tasks scheduled from follow-on schedule check
