[2025-08-06T22:06:06.614+0000] {scheduler_job_runner.py:1586} WARNING - Marking task instance <TaskInstance: Ejercicio1.Inicio scheduled__2025-08-05T00:00:00+00:00 [queued]> stuck in queued as failed. If the task instance has available retries, it will be retried.
[2025-08-06T22:06:10.934+0000] {scheduler_job_runner.py:781} ERROR - Executor reports task instance <TaskInstance: Ejercicio1.Inicio scheduled__2025-08-05T00:00:00+00:00 [queued]> finished (failed) although the task says it's queued. (Info: None) Was the task killed externally?
