[2025-08-06T23:27:33.857+0000] {taskinstance.py:1956} INFO - Dependencies all met for dep_context=non-requeueable deps ti=<TaskInstance: Ejercicio2.Inicio manual__2025-08-06T23:27:28.083550+00:00 [queued]>
[2025-08-06T23:27:33.912+0000] {taskinstance.py:1956} INFO - Dependencies all met for dep_context=requeueable deps ti=<TaskInstance: Ejercicio2.Inicio manual__2025-08-06T23:27:28.083550+00:00 [queued]>
[2025-08-06T23:27:33.915+0000] {taskinstance.py:2170} INFO - Starting attempt 1 of 2
[2025-08-06T23:27:33.977+0000] {taskinstance.py:2191} INFO - Executing <Task(BranchPythonOperator): Inicio> on 2025-08-06 23:27:28.083550+00:00
[2025-08-06T23:27:34.001+0000] {standard_task_runner.py:60} INFO - Started process 4738 to run task
[2025-08-06T23:27:34.006+0000] {standard_task_runner.py:87} INFO - Running: ['***', 'tasks', 'run', 'Ejercicio2', 'Inicio', 'manual__2025-08-06T23:27:28.083550+00:00', '--job-id', '286', '--raw', '--subdir', 'DAGS_FOLDER/ejercicio2.py', '--cfg-path', '/tmp/tmpf8sy749o']
[2025-08-06T23:27:34.017+0000] {standard_task_runner.py:88} INFO - Job 286: Subtask Inicio
[2025-08-06T23:27:34.193+0000] {task_command.py:423} INFO - Running <TaskInstance: Ejercicio2.Inicio manual__2025-08-06T23:27:28.083550+00:00 [running]> on host 019b67754667
[2025-08-06T23:27:34.522+0000] {taskinstance.py:2480} INFO - Exporting env vars: AIRFLOW_CTX_DAG_OWNER='***' AIRFLOW_CTX_DAG_ID='Ejercicio2' AIRFLOW_CTX_TASK_ID='Inicio' AIRFLOW_CTX_EXECUTION_DATE='2025-08-06T23:27:28.083550+00:00' AIRFLOW_CTX_TRY_NUMBER='1' AIRFLOW_CTX_DAG_RUN_ID='manual__2025-08-06T23:27:28.083550+00:00'
[2025-08-06T23:27:37.077+0000] {_client.py:1038} INFO - HTTP Request: GET https://qwpzsjaaxuijmqodvslf.supabase.co/rest/v1/cotizaciones?select=%2A "HTTP/2 200 OK"
[2025-08-06T23:27:37.105+0000] {logging_mixin.py:188} INFO - 
 ----------------------
data=[] count=None
[2025-08-06T23:27:37.107+0000] {taskinstance.py:2698} ERROR - Task failed with exception
Traceback (most recent call last):
  File "/home/airflow/.local/lib/python3.8/site-packages/airflow/models/taskinstance.py", line 433, in _execute_task
    result = execute_callable(context=context, **execute_callable_kwargs)
  File "/home/airflow/.local/lib/python3.8/site-packages/airflow/operators/python.py", line 233, in execute
    return self.do_branch(context, super().execute(context))
  File "/home/airflow/.local/lib/python3.8/site-packages/airflow/operators/python.py", line 199, in execute
    return_value = self.execute_callable()
  File "/home/airflow/.local/lib/python3.8/site-packages/airflow/operators/python.py", line 216, in execute_callable
    return self.python_callable(*self.op_args, **self.op_kwargs)
  File "/opt/airflow/dags/ejercicio2.py", line 94, in inicio
    if cotizaciones['data'] != []:
TypeError: 'APIResponse[~_ReturnT]' object is not subscriptable
[2025-08-06T23:27:37.160+0000] {taskinstance.py:1138} INFO - Marking task as UP_FOR_RETRY. dag_id=Ejercicio2, task_id=Inicio, execution_date=20250806T232728, start_date=20250806T232733, end_date=20250806T232737
[2025-08-06T23:27:37.212+0000] {standard_task_runner.py:107} ERROR - Failed to execute job 286 for task Inicio ('APIResponse[~_ReturnT]' object is not subscriptable; 4738)
[2025-08-06T23:27:37.290+0000] {local_task_job_runner.py:234} INFO - Task exited with return code 1
[2025-08-06T23:27:37.378+0000] {taskinstance.py:3280} INFO - 0 downstream tasks scheduled from follow-on schedule check
